Workbook

Sheet Monitor_2025
A1: Entidad | B1: Variable | C1: Valor | D1: Que_mide | E1: Unidad | F1: Fuente
A2: Aguascalientes | B2: Brecha de ingresos por género | C2: 14.720139 | D2: Valor absoluto de la diferencia de ingresos mensuales promedio de hombres y mujeres dividida entre los ingresos mensuales promedio de los hombres | E2: Porcentaje | F2: Elaborado por el IMCO con datos del 3T2024 de la Encuesta Nacional de Ocupación y Empleo (ENOE) del INEGI.
A3: Baja California | B3: Brecha de ingresos por género | C3: 14.883748 | D3: Valor absoluto de la diferencia de ingresos mensuales promedio de hombres y mujeres dividida entre los ingresos mensuales promedio de los hombres | E3: Porcentaje | F3: Elaborado por el IMCO con datos del 3T2024 de la Encuesta Nacional de Ocupación y Empleo (ENOE) del INEGI.
A4: Baja California Sur | B4: Brecha de ingresos por género | C4: 13.275317 | D4: Valor absoluto de la diferencia de ingresos mensuales promedio de hombres y mujeres dividida entre los ingresos mensuales promedio de los hombres | E4: Porcentaje | F4: Elaborado por el IMCO con datos del 3T2024 de la Encuesta Nacional de Ocupación y Empleo (ENOE) del INEGI.
A5: Campeche | B5: Brecha de ingresos por género | C5: 6.5688031 | D5: Valor absoluto de la diferencia de ingresos mensuales promedio de hombres y mujeres dividida entre los ingresos mensuales promedio de los hombres | E5: Porcentaje | F5: Elaborado por el IMCO con datos del 3T2024 de la Encuesta Nacional de Ocupación y Empleo (ENOE) del INEGI.
A6: Chiapas | B6: Brecha de ingresos por género | C6: 4.6652654 | D6: Valor absoluto de la diferencia de ingresos mensuales promedio de hombres y mujeres dividida entre los ingresos mensuales promedio de los hombres | E6: Porcentaje | F6: Elaborado por el IMCO con datos del 3T2024 de la Encuesta Nacional de Ocupación y Empleo (ENOE) del INEGI.
A7: Chihuahua | B7: Brecha de ingresos por género | C7: 14.788325 | D7: Valor absoluto de la diferencia de ingresos mensuales promedio de hombres y mujeres dividida entre los ingresos mensuales promedio de los hombres | E7: Porcentaje | F7: Elaborado por el IMCO con datos del 3T2024 de la Encuesta Nacional de Ocupación y Empleo (ENOE) del INEGI.
A8: Ciudad de México | B8: Brecha de ingresos por género | C8: 9.5998725 | D8: Valor absoluto de la diferencia de ingresos mensuales promedio de hombres y mujeres dividida entre los ingresos mensuales promedio de los hombres | E8: Porcentaje | F8: Elaborado por el IMCO con datos del 3T2024 de la Encuesta Nacional de Ocupación y Empleo (ENOE) del INEGI.
A9: Coahuila | B9: Brecha de ingresos por género | C9: 17.773609 | D9: Valor absoluto de la diferencia de ingresos mensuales promedio de hombres y mujeres dividida entre los ingresos mensuales promedio de los hombres | E9: Porcentaje | F9: Elaborado por el IMCO con datos del 3T2024 de la Encuesta Nacional de Ocupación y Empleo (ENOE) del INEGI.
A10: Colima | B10: Brecha de ingresos por género | C10: 18.919594 | D10: Valor absoluto de la diferencia de ingresos mensuales promedio de hombres y mujeres dividida entre los ingresos mensuales promedio de los hombres | E10: Porcentaje | F10: Elaborado por el IMCO con datos del 3T2024 de la Encuesta Nacional de Ocupación y Empleo (ENOE) del INEGI.
A11: Durango | B11: Brecha de ingresos por género | C11: 15.281833 | D11: Valor absoluto de la diferencia de ingresos mensuales promedio de hombres y mujeres dividida entre los ingresos mensuales promedio de los hombres | E11: Porcentaje | F11: Elaborado por el IMCO con datos del 3T2024 de la Encuesta Nacional de Ocupación y Empleo (ENOE) del INEGI.
A12: Guanajuato | B12: Brecha de ingresos por género | C12: 16.85093 | D12: Valor absoluto de la diferencia de ingresos mensuales promedio de hombres y mujeres dividida entre los ingresos mensuales promedio de los hombres | E12: Porcentaje | F12: Elaborado por el IMCO con datos del 3T2024 de la Encuesta Nacional de Ocupación y Empleo (ENOE) del INEGI.
A13: Guerrero | B13: Brecha de ingresos por género | C13: 23.017352 | D13: Valor absoluto de la diferencia de ingresos mensuales promedio de hombres y mujeres dividida entre los ingresos mensuales promedio de los hombres | E13: Porcentaje | F13: Elaborado por el IMCO con datos del 3T2024 de la Encuesta Nacional de Ocupación y Empleo (ENOE) del INEGI.
... A545: Zacatecas | B545: Tasa de participación económica de mujeres | C545: 41.040352 | D545: Mujeres de 15 años y más que tienen un empleo o que buscan uno | E545: Porcentaje | F545: Elaborado por el IMCO con datos del 3T2024 de la Encuesta Nacional de Ocupación y Empleo (ENOE) del INEGI.

Sheet Indice2026
A2: Subíndice | B2: Ancla | C2: Entrada | I2: Permanencia | O2: Autonomía económica | S2: <
A3: Nombre del Indicador | B3: Tasa de participación económica femenina | C3: Mujeres preparadas | D3: Embarazo adolescente | E3: Desigualdad en trabajo no remunerado | F3: Inseguridad en el transporte público | G3: Homicidios dolosos de mujeres | H3: Mujeres que quieren trabajar y no pueden | I3: Brecha de ingresos por género | J3: Informalidad | K3: Cobertura de cuidados en la primera infancia | L3: Oferta de cuidados de adultos mayores | M3: Permisos de paternidad | N3: Delitos sexuales | O3: Pobreza laboral | P3: Dependencia de ingresos | Q3: Emprendedoras formales | R3: Propiedad de la vivienda
A4: Clave variable | B4: Ancla | C4: Prep | D4: Embarazo | E4: TNR | F4: Inseg_TP | G4: Homicidios | H4: Brecha_lab | I4: Brecha_ing | J4: Informalidad | K4: Cuidados_inf | L4: Cuidados_adult | M4: Paternidad | N4: Del_sex | O4: Pob_lab | P4: Ind_eco | Q4: Emp_form | R4: Vivienda
A5: Qué mide | B5: Mujeres de 15 años y más que tienen un empleo o que buscan uno | C5: Porcentaje de mujeres de 18 años y más con al menos educación media superior | D5: Porcentaje de nacimientos registrados de madres menores de 20 años | E5: Porcentaje adicional de horas semanales que dedica una mujer al TNR en comparación con un hombre | F5: Porcentaje de mujeres que dejaron de usar transporte público por temor a ser víctima de algún delito | G5: Mujeres víctimas de homicidios dolosos y feminicidios por cada 100 mil mujeres | H5: Porcentaje de trabajadoras potenciales desocupadas, subocupadas o disponibles pero no activas en la economía | I5: Valor absoluto de la diferencia de ingresos mensuales promedio de hombres y mujeres dividida entre los ingresos mensuales promedio de los hombres | J5: Porcentaje de mujeres ocupadas no agropecuarias en la informalidad | K5: Porcentaje de infancias de 0 a 5 años inscritos en una guardería, centro de cuidados o preescolar | L5: Unidades de cuidados para adultos mayores por cada 100 mil habitantes de 65 años y más | M5: Días de permiso de paternidad remunerados para los trabajadores del gobierno del Estado | N5: Carpetas de investigación de delitos de acoso y hostigamiento sexual por cada 100 mil mujeres | O5: Mujeres con ingreso laboral inferior al costo de la canasta alimentaria | P5: Proporción de mujeres de 15 años y más que no percibe ingresos monetarios directos | Q5: Porcentaje de emprendedoras en la formalidad | R5: Porcentaje de mujeres con propiedad o copropiedad legal de vivienda
A6: Unidad de Medida | B6: Porcentaje | C6: Porcentaje | D6: Porcentaje | E6: Porcentaje | F6: Porcentaje | G6: Tasa | H6: Porcentaje | I6: Porcentaje | J6: Porcentaje | K6: Porcentaje | L6: Tasa | M6: Días | N6: Tasa | O6: Porcentaje | P6: Porcentaje | Q6: Porcentaje | R6: Porcentaje
A7: Fuente | B7: ENOE, INEGI | C7: ENOE, INEGI | D7: Estadísticas de Natalidad, INEGI | E7: Cuenta Satélite del Trabajo No Remunerado de los Hogares de México, INEGI | F7: ENVIPE, INEGI | G7: Observatorio Nacional Ciudadano con datos del Secretariado Ejecutivo del Sistema Nacional de Seguridad Pública y Conapo | H7: ENOE, INEGI | I7: ENOE, INEGI | J7: ENOE, INEGI | K7: IMCO con formatos 911 de la SEP, Conapo e IMSS | L7: IMCO con datos Denue, INEGI y Conapo | M7: IMCO con Leyes del Trabajo de los Servidores Públicos al Servicio del Estado vigentes | N7: Observatorio Nacional Ciudadano con datos del Secretariado Ejecutivo del Sistema Nacional de Seguridad Pública y Conapo | O7: México, ¿Cómo Vamos? con datos del Índice de Tendencia Laboral de la Pobreza por Intervalo de Salarios del Coneval | P7: ENIGH, INEGI | Q7: ENOE, INEGI | R7: ENIGH, INEGI
A8: Año de referencia | B8: 3T 2025 | C8: 3T 2025 | D8: 2024 (actualiza en sept) | E8: 2024 | F8: 2024 (actualiza en sept) | G8: 2025 | H8: 3T 2025 | I8: 3T 2025 | J8: 3T 2025 | K8: 2024 | L8: 2025 | M8: 2026 | N8: 2025 | O8: 3T 2025 | P8: 2024 | Q8: 3T 2025 | R8: 2024
A9: Periodicidad de la fuente | B9: Trimestral | C9: Trimestral | D9: Anual | E9: Anual | F9: Anual | G9: Anual | H9: Trimestral | I9: Trimestral | J9: Trimestral | K9: Anual | L9: Anual | M9: Fecha de corte | N9: Anual | O9: Trimestral | P9: Bianual | Q9: Trimestral | R9: Bianual
A10: ¿Más es mejor? | B10: Sí | C10: Sí | D10: No | E10: No | F10: No | G10: No | H10: No | I10: No | J10: No | K10: Sí | L10: Sí | M10: Sí | N10: No | O10: No | P10: No | Q10: Sí | R10: Sí
A11: Nacional | B11: 45.719953 | C11: 45.125083 | D11: 14.6 | E11: 58.388484 | F11: 25.2 | G11: 4.1118439 | H11: 20.769935 | I11: 11.374183 | J11: 54.8117 | K11: 37.689731 | L11: 11.326239 | M11: 5 | N11: 21.278535 | O11: 36.2 | P11: 26.086509 | Q11: 15.918031 | R11: 16.012576
A12: Promedio nacional | B12: 46.818313 | C12: 44.682305 | D12: 14.315625 | E12: 57.688561 | F12: 23.95 | G12: 4.6725711 | H12: 20.616734 | I12: 13.922654 | J12: 54.663497 | K12: 39.055067 | L12: 12.6197 | M12: 23.03125 | N12: 20.741428 | O12: 34.55 | P12: 25.619981 | Q12: 17.903246 | R12: 17.035952 | S12: 30
A13: Aguascalientes | B13: 44.374304 | C13: 47.459684 | D13: 14 | E13: 57.398267 | F13: 24.6 | G13: 0.88634185 | H13: 14.766362 | I13: 10.592206 | J13: 41.7848 | K13: 40.097819 | L13: 21.446893 | M13: 10 | N13: 18.613179 | O13: 33.7 | P13: 22.440227 | Q13: 24.627773 | R13: 18.171666 | S13: Aguascalientes
A14: Baja California | B14: 46.731801 | C14: 48.046475 | D14: 11.2 | E14: 48.100431 | F14: 28 | G14: 10.968369 | H14: 13.574198 | I14: 11.059407 | J14: 36.8692 | K14: 33.946358 | L14: 17.644579 | M14: 5 | N14: 80.565869 | O14: 20.8 | P14: 18.153913 | Q14: 22.254182 | R14: 16.956317 | S14: Baja California
A15: Baja California Sur | B15: 55.838902 | C15: 53.831557 | D15: 12.1 | E15: 52.344111 | F15: 19.9 | G15: 3.838893 | H15: 15.364818 | I15: 16.807657 | J15: 39.127 | K15: 37.128528 | L15: 6.4653779 | M15: 84 | N15: 41.324554 | O15: 14.4 | P15: 17.134063 | Q15: 27.897957 | R15: 19.103132 | S15: Baja California Sur
A16: Campeche | B16: 44.878432 | C16: 44.212024 | D16: 14.4 | E16: 58.265717 | F16: 19.2 | G16: 2.6626195 | H16: 27.200616 | I16: 9.4676232 | J16: 59.4185 | K16: 42.467803 | L16: 13.961694 | M16: 15 | N16: 5.325239 | O16: 37 | P16: 22.108955 | Q16: 14.478186 | R16: 23.330078 | S16: Campeche
A17: Coahuila | B17: 45.675182 | C17: 46.323161 | D17: 15.7 | E17: 60.427169 | F17: 20.4 | G17: 0.70489384 | H17: 14.234483 | I17: 11.643709 | J17: 36.7823 | K17: 44.574509 | L17: 12.12212 | M17: 10 | N17: 33.776163 | O17: 25.8 | P17: 19.26325 | Q17: 17.473441 | R17: 17.634276 | S17: Coahuila de Zaragoza
A18: Colima | B18: 56.564427 | C18: 49.808072 | D18: 12.9 | E18: 55.008738 | F18: 37.9 | G18: 25.306323 | H18: 12.89675 | I18: 17.959703 | J18: 49.9393 | K18: 47.907459 | L18: 31.672588 | M18: 20 | N18: 37.701256 | O18: 20.2 | P18: 21.643647 | Q18: 29.223556 | R18: 20.767517 | S18: Colima
A19: Chiapas | B19: 32.469794 | C19: 29.115126 | D19: 18.3 | E19: 67.174294 | F19: 21.5 | G19: 1.9192102 | H19: 28.80434 | I19: 0.11962593 | J19: 71.3841 | K19: 36.820917 | L19: 3.9579298 | M19: 30 | N19: 2.5269601 | O19: 62.9 | P19: 27.776093 | Q19: 13.969202 | R19: 12.396625 | S19: Chiapas
A20: Chihuahua | B20: 46.949908 | C20: 47.713388 | D20: 17.7 | E20: 56.012721 | F20: 32.6 | G20: 8.5047721 | H20: 17.962268 | I20: 11.03736 | J20: 31.0851 | K20: 38.376758 | L20: 26.214559 | M20: 5 | N20: 26.058226 | O20: 24.5 | P20: 19.343119 | Q20: 28.879425 | R20: 19.547277 | S20: Chihuahua
A21: Ciudad de México | B21: 54.699544 | C21: 63.384296 | D21: 10.2 | E21: 46.269687 | F21: 25.2 | G21: 2.4499473 | H21: 22.18002 | I21: 4.6352318 | J21: 47.0387 | K21: 43.79633 | L21: 9.4862128 | M21: 42 | N21: 31.912134 | O21: 25.4 | P21: 20.974189 | Q21: 20.290387 | R21: 17.316256 | S21: Ciudad de México
A22: Durango | B22: 46.495426 | C22: 45.097585 | D22: 15.8 | E22: 57.383118 | F22: 22.1 | G22: 0.72021574 | H22: 20.397652 | I22: 13.918399 | J22: 51.9795 | K22: 39.229684 | L22: 12.816992 | M22: 5 | N22: 10.803236 | O22: 34.9 | P22: 26.332365 | Q22: 14.070142 | R22: 17.005714 | S22: Durango
A23: Guanajuato | B23: 46.171019 | C23: 37.407342 | D23: 14.6 | E23: 63.241039 | F23: 27.8 | G23: 10.262424 | H23: 30.757069 | I23: 10.336336 | J23: 52.8618 | K23: 37.992469 | L23: 11.807381 | M23: 5 | N23: 15.408508 | O23: 35.9 | P23: 30.180147 | Q23: 17.828628 | R23: 15.660868 | S23: Guanajuato
A24: Guerrero | B24: 46.844048 | C24: 36.484708 | D24: 17.1 | E24: 60.247582 | F24: 17.5 | G24: 7.1616546 | H24: 17.891231 | I24: 23.561238 | J24: 74.5804 | K24: 41.445124 | L24: 4.6012552 | M24: 30 | N24: 9.9942493 | O24: 53.7 | P24: 34.896884 | Q24: 5.8546731 | R24: 18.696321 | S24: Guerrero
... A44: Zacatecas | B44: 40.71148 | C44: 36.581517 | D44: 14.6 | E44: 61.121486 | F44: 35.3 | G44: 2.7427537 | H44: 21.82062 | I44: 12.191667 | J44: 53.566 | K44: 41.11345 | L44: 13.411927 | M44: 45 | N44: 18.170743 | O44: 43.9 | P44: 36.721016 | Q44: 30.906088 | R44: 14.562865 | S44: Zacatecas

Sheet Monitor_2026
A1: Entidad | B1: Variable | C1: Valor | D1: Que_mide | E1: Unidad | F1: Fuente
A2: Aguascalientes | B2: =TRIM(Indice2026!$I$3) -> Brecha de ingresos por género | C2: =Indice2026!I13 -> 10.592206 | D2: =TRIM(Indice2026!$I$5) -> Valor absoluto de la diferencia de ingresos mensuales promedio de hombres y mujeres dividida entre los ingresos mensuales promedio de los hombres | E2: =TRIM(Indice2026!$I$6) -> Porcentaje | F2: Elaborado por el IMCO con datos del 3T2025 de la Encuesta Nacional de Ocupación y Empleo (ENOE) del INEGI.
A3: Baja California | B3: =TRIM(Indice2026!$I$3) -> Brecha de ingresos por género | C3: =Indice2026!I14 -> 11.059407 | D3: =TRIM(Indice2026!$I$5) -> Valor absoluto de la diferencia de ingresos mensuales promedio de hombres y mujeres dividida entre los ingresos mensuales promedio de los hombres | E3: =TRIM(Indice2026!$I$6) -> Porcentaje | F3: Elaborado por el IMCO con datos del 3T2025 de la Encuesta Nacional de Ocupación y Empleo (ENOE) del INEGI.
A4: Baja California Sur | B4: =TRIM(Indice2026!$I$3) -> Brecha de ingresos por género | C4: =Indice2026!I15 -> 16.807657 | D4: =TRIM(Indice2026!$I$5) -> Valor absoluto de la diferencia de ingresos mensuales promedio de hombres y mujeres dividida entre los ingresos mensuales promedio de los hombres | E4: =TRIM(Indice2026!$I$6) -> Porcentaje | F4: Elaborado por el IMCO con datos del 3T2025 de la Encuesta Nacional de Ocupación y Empleo (ENOE) del INEGI.
A5: Campeche | B5: =TRIM(Indice2026!$I$3) -> Brecha de ingresos por género | C5: =Indice2026!I16 -> 9.4676232 | D5: =TRIM(Indice2026!$I$5) -> Valor absoluto de la diferencia de ingresos mensuales promedio de hombres y mujeres dividida entre los ingresos mensuales promedio de los hombres | E5: =TRIM(Indice2026!$I$6) -> Porcentaje | F5: Elaborado por el IMCO con datos del 3T2025 de la Encuesta Nacional de Ocupación y Empleo (ENOE) del INEGI.
A6: Chiapas | B6: =TRIM(Indice2026!$I$3) -> Brecha de ingresos por género | C6: =Indice2026!I19 -> 0.11962593 | D6: =TRIM(Indice2026!$I$5) -> Valor absoluto de la diferencia de ingresos mensuales promedio de hombres y mujeres dividida entre los ingresos mensuales promedio de los hombres | E6: =TRIM(Indice2026!$I$6) -> Porcentaje | F6: Elaborado por el IMCO con datos del 3T2025 de la Encuesta Nacional de Ocupación y Empleo (ENOE) del INEGI.
A7: Chihuahua | B7: =TRIM(Indice2026!$I$3) -> Brecha de ingresos por género | C7: =Indice2026!I20 -> 11.03736 | D7: =TRIM(Indice2026!$I$5) -> Valor absoluto de la diferencia de ingresos mensuales promedio de hombres y mujeres dividida entre los ingresos mensuales promedio de los hombres | E7: =TRIM(Indice2026!$I$6) -> Porcentaje | F7: Elaborado por el IMCO con datos del 3T2025 de la Encuesta Nacional de Ocupación y Empleo (ENOE) del INEGI.
A8: Ciudad de México | B8: =TRIM(Indice2026!$I$3) -> Brecha de ingresos por género | C8: =Indice2026!I21 -> 4.6352318 | D8: =TRIM(Indice2026!$I$5) -> Valor absoluto de la diferencia de ingresos mensuales promedio de hombres y mujeres dividida entre los ingresos mensuales promedio de los hombres | E8: =TRIM(Indice2026!$I$6) -> Porcentaje | F8: Elaborado por el IMCO con datos del 3T2025 de la Encuesta Nacional de Ocupación y Empleo (ENOE) del INEGI.
A9: Coahuila | B9: =TRIM(Indice2026!$I$3) -> Brecha de ingresos por género | C9: =Indice2026!I17 -> 11.643709 | D9: =TRIM(Indice2026!$I$5) -> Valor absoluto de la diferencia de ingresos mensuales promedio de hombres y mujeres dividida entre los ingresos mensuales promedio de los hombres | E9: =TRIM(Indice2026!$I$6) -> Porcentaje | F9: Elaborado por el IMCO con datos del 3T2025 de la Encuesta Nacional de Ocupación y Empleo (ENOE) del INEGI.
A10: Colima | B10: =TRIM(Indice2026!$I$3) -> Brecha de ingresos por género | C10: =Indice2026!I18 -> 17.959703 | D10: =TRIM(Indice2026!$I$5) -> Valor absoluto de la diferencia de ingresos mensuales promedio de hombres y mujeres dividida entre los ingresos mensuales promedio de los hombres | E10: =TRIM(Indice2026!$I$6) -> Porcentaje | F10: Elaborado por el IMCO con datos del 3T2025 de la Encuesta Nacional de Ocupación y Empleo (ENOE) del INEGI.
A11: Durango | B11: =TRIM(Indice2026!$I$3) -> Brecha de ingresos por género | C11: =Indice2026!I22 -> 13.918399 | D11: =TRIM(Indice2026!$I$5) -> Valor absoluto de la diferencia de ingresos mensuales promedio de hombres y mujeres dividida entre los ingresos mensuales promedio de los hombres | E11: =TRIM(Indice2026!$I$6) -> Porcentaje | F11: Elaborado por el IMCO con datos del 3T2025 de la Encuesta Nacional de Ocupación y Empleo (ENOE) del INEGI.
A12: Guanajuato | B12: =TRIM(Indice2026!$I$3) -> Brecha de ingresos por género | C12: =Indice2026!I23 -> 10.336336 | D12: =TRIM(Indice2026!$I$5) -> Valor absoluto de la diferencia de ingresos mensuales promedio de hombres y mujeres dividida entre los ingresos mensuales promedio de los hombres | E12: =TRIM(Indice2026!$I$6) -> Porcentaje | F12: Elaborado por el IMCO con datos del 3T2025 de la Encuesta Nacional de Ocupación y Empleo (ENOE) del INEGI.
A13: Guerrero | B13: =TRIM(Indice2026!$I$3) -> Brecha de ingresos por género | C13: =Indice2026!I24 -> 23.561238 | D13: =TRIM(Indice2026!$I$5) -> Valor absoluto de la diferencia de ingresos mensuales promedio de hombres y mujeres dividida entre los ingresos mensuales promedio de los hombres | E13: =TRIM(Indice2026!$I$6) -> Porcentaje | F13: Elaborado por el IMCO con datos del 3T2025 de la Encuesta Nacional de Ocupación y Empleo (ENOE) del INEGI.
A14: Hidalgo | B14: =TRIM(Indice2026!$I$3) -> Brecha de ingresos por género | C14: =Indice2026!I25 -> 17.472399 | D14: =TRIM(Indice2026!$I$5) -> Valor absoluto de la diferencia de ingresos mensuales promedio de hombres y mujeres dividida entre los ingresos mensuales promedio de los hombres | E14: =TRIM(Indice2026!$I$6) -> Porcentaje | F14: Elaborado por el IMCO con datos del 3T2025 de la Encuesta Nacional de Ocupación y Empleo (ENOE) del INEGI.
A15: Jalisco | B15: =TRIM(Indice2026!$I$3) -> Brecha de ingresos por género | C15: =Indice2026!I26 -> 15.135771 | D15: =TRIM(Indice2026!$I$5) -> Valor absoluto de la diferencia de ingresos mensuales promedio de hombres y mujeres dividida entre los ingresos mensuales promedio de los hombres | E15: =TRIM(Indice2026!$I$6) -> Porcentaje | F15: Elaborado por el IMCO con datos del 3T2025 de la Encuesta Nacional de Ocupación y Empleo (ENOE) del INEGI.
A16: Michoacán | B16: =TRIM(Indice2026!$I$3) -> Brecha de ingresos por género | C16: =Indice2026!I28 -> 15.085179 | D16: =TRIM(Indice2026!$I$5) -> Valor absoluto de la diferencia de ingresos mensuales promedio de hombres y mujeres dividida entre los ingresos mensuales promedio de los hombres | E16: =TRIM(Indice2026!$I$6) -> Porcentaje | F16: Elaborado por el IMCO con datos del 3T2025 de la Encuesta Nacional de Ocupación y Empleo (ENOE) del INEGI.
A17: Morelos | B17: =TRIM(Indice2026!$I$3) -> Brecha de ingresos por género | C17: =Indice2026!I29 -> 21.562938 | D17: =TRIM(Indice2026!$I$5) -> Valor absoluto de la diferencia de ingresos mensuales promedio de hombres y mujeres dividida entre los ingresos mensuales promedio de los hombres | E17: =TRIM(Indice2026!$I$6) -> Porcentaje | F17: Elaborado por el IMCO con datos del 3T2025 de la Encuesta Nacional de Ocupación y Empleo (ENOE) del INEGI.
A18: México | B18: =TRIM(Indice2026!$I$3) -> Brecha de ingresos por género | C18: =Indice2026!I27 -> 11.571408 | D18: =TRIM(Indice2026!$I$5) -> Valor absoluto de la diferencia de ingresos mensuales promedio de hombres y mujeres dividida entre los ingresos mensuales promedio de los hombres | E18: =TRIM(Indice2026!$I$6) -> Porcentaje | F18: Elaborado por el IMCO con datos del 3T2025 de la Encuesta Nacional de Ocupación y Empleo (ENOE) del INEGI.
A19: Nayarit | B19: =TRIM(Indice2026!$I$3) -> Brecha de ingresos por género | C19: =Indice2026!I30 -> 14.533136 | D19: =TRIM(Indice2026!$I$5) -> Valor absoluto de la diferencia de ingresos mensuales promedio de hombres y mujeres dividida entre los ingresos mensuales promedio de los hombres | E19: =TRIM(Indice2026!$I$6) -> Porcentaje | F19: Elaborado por el IMCO con datos del 3T2025 de la Encuesta Nacional de Ocupación y Empleo (ENOE) del INEGI.
A20: Nuevo León | B20: =TRIM(Indice2026!$I$3) -> Brecha de ingresos por género | C20: =Indice2026!I31 -> 19.330952 | D20: =TRIM(Indice2026!$I$5) -> Valor absoluto de la diferencia de ingresos mensuales promedio de hombres y mujeres dividida entre los ingresos mensuales promedio de los hombres | E20: =TRIM(Indice2026!$I$6) -> Porcentaje | F20: Elaborado por el IMCO con datos del 3T2025 de la Encuesta Nacional de Ocupación y Empleo (ENOE) del INEGI.
A21: Oaxaca | B21: =TRIM(Indice2026!$I$3) -> Brecha de ingresos por género | C21: =Indice2026!I32 -> 19.048902 | D21: =TRIM(Indice2026!$I$5) -> Valor absoluto de la diferencia de ingresos mensuales promedio de hombres y mujeres dividida entre los ingresos mensuales promedio de los hombres | E21: =TRIM(Indice2026!$I$6) -> Porcentaje | F21: Elaborado por el IMCO con datos del 3T2025 de la Encuesta Nacional de Ocupación y Empleo (ENOE) del INEGI.
A22: Puebla | B22: =TRIM(Indice2026!$I$3) -> Brecha de ingresos por género | C22: =Indice2026!I33 -> 12.908157 | D22: =TRIM(Indice2026!$I$5) -> Valor absoluto de la diferencia de ingresos mensuales promedio de hombres y mujeres dividida entre los ingresos mensuales promedio de los hombres | E22: =TRIM(Indice2026!$I$6) -> Porcentaje | F22: Elaborado por el IMCO con datos del 3T2025 de la Encuesta Nacional de Ocupación y Empleo (ENOE) del INEGI.
A23: Querétaro | B23: =TRIM(Indice2026!$I$3) -> Brecha de ingresos por género | C23: =Indice2026!I34 -> 19.713498 | D23: =TRIM(Indice2026!$I$5) -> Valor absoluto de la diferencia de ingresos mensuales promedio de hombres y mujeres dividida entre los ingresos mensuales promedio de los hombres | E23: =TRIM(Indice2026!$I$6) -> Porcentaje | F23: Elaborado por el IMCO con datos del 3T2025 de la Encuesta Nacional de Ocupación y Empleo (ENOE) del INEGI.
A24: Quintana Roo | B24: =TRIM(Indice2026!$I$3) -> Brecha de ingresos por género | C24: =Indice2026!I35 -> 15.755918 | D24: =TRIM(Indice2026!$I$5) -> Valor absoluto de la diferencia de ingresos mensuales promedio de hombres y mujeres dividida entre los ingresos mensuales promedio de los hombres | E24: =TRIM(Indice2026!$I$6) -> Porcentaje | F24: Elaborado por el IMCO con datos del 3T2025 de la Encuesta Nacional de Ocupación y Empleo (ENOE) del INEGI.
A25: San Luis Potosí | B25: =TRIM(Indice2026!$I$3) -> Brecha de ingresos por género | C25: =Indice2026!I36 -> 10.043066 | D25: =TRIM(Indice2026!$I$5) -> Valor absoluto de la diferencia de ingresos mensuales promedio de hombres y mujeres dividida entre los ingresos mensuales promedio de los hombres | E25: =TRIM(Indice2026!$I$6) -> Porcentaje | F25: Elaborado por el IMCO con datos del 3T2025 de la Encuesta Nacional de Ocupación y Empleo (ENOE) del INEGI.
A26: Sinaloa | B26: =TRIM(Indice2026!$I$3) -> Brecha de ingresos por género | C26: =Indice2026!I37 -> 16.977324 | D26: =TRIM(Indice2026!$I$5) -> Valor absoluto de la diferencia de ingresos mensuales promedio de hombres y mujeres dividida entre los ingresos mensuales promedio de los hombres | E26: =TRIM(Indice2026!$I$6) -> Porcentaje | F26: Elaborado por el IMCO con datos del 3T2025 de la Encuesta Nacional de Ocupación y Empleo (ENOE) del INEGI.
A27: Sonora | B27: =TRIM(Indice2026!$I$3) -> Brecha de ingresos por género | C27: =Indice2026!I38 -> 14.913534 | D27: =TRIM(Indice2026!$I$5) -> Valor absoluto de la diferencia de ingresos mensuales promedio de hombres y mujeres dividida entre los ingresos mensuales promedio de los hombres | E27: =TRIM(Indice2026!$I$6) -> Porcentaje | F27: Elaborado por el IMCO con datos del 3T2025 de la Encuesta Nacional de Ocupación y Empleo (ENOE) del INEGI.
A28: Tabasco | B28: =TRIM(Indice2026!$I$3) -> Brecha de ingresos por género | C28: =Indice2026!I39 -> 17.75804 | D28: =TRIM(Indice2026!$I$5) -> Valor absoluto de la diferencia de ingresos mensuales promedio de hombres y mujeres dividida entre los ingresos mensuales promedio de los hombres | E28: =TRIM(Indice2026!$I$6) -> Porcentaje | F28: Elaborado por el IMCO con datos del 3T2025 de la Encuesta Nacional de Ocupación y Empleo (ENOE) del INEGI.
A29: Tamaulipas | B29: =TRIM(Indice2026!$I$3) -> Brecha de ingresos por género | C29: =Indice2026!I40 -> 8.2901726 | D29: =TRIM(Indice2026!$I$5) -> Valor absoluto de la diferencia de ingresos mensuales promedio de hombres y mujeres dividida entre los ingresos mensuales promedio de los hombres | E29: =TRIM(Indice2026!$I$6) -> Porcentaje | F29: Elaborado por el IMCO con datos del 3T2025 de la Encuesta Nacional de Ocupación y Empleo (ENOE) del INEGI.
A30: Tlaxcala | B30: =TRIM(Indice2026!$I$3) -> Brecha de ingresos por género | C30: =Indice2026!I41 -> 18.216217 | D30: =TRIM(Indice2026!$I$5) -> Valor absoluto de la diferencia de ingresos mensuales promedio de hombres y mujeres dividida entre los ingresos mensuales promedio de los hombres | E30: =TRIM(Indice2026!$I$6) -> Porcentaje | F30: Elaborado por el IMCO con datos del 3T2025 de la Encuesta Nacional de Ocupación y Empleo (ENOE) del INEGI.
... A33: Zacatecas | B33: =TRIM(Indice2026!$I$3) -> Brecha de ingresos por género | C33: =Indice2026!I44 -> 12.191667 | D33: =TRIM(Indice2026!$I$5) -> Valor absoluto de la diferencia de ingresos mensuales promedio de hombres y mujeres dividida entre los ingresos mensuales promedio de los hombres | E33: =TRIM(Indice2026!$I$6) -> Porcentaje | F33: Elaborado por el IMCO con datos del 3T2025 de la Encuesta Nacional de Ocupación y Empleo (ENOE) del INEGI.
A34: Aguascalientes | B34: =TRIM(Indice2026!$K$3) -> Cobertura de cuidados en la primera infancia | C34: =Indice2026!K13 -> 40.097819 | D34: =TRIM(Indice2026!$K$5) -> Porcentaje de infancias de 0 a 5 años inscritos en una guardería, centro de cuidados o preescolar | E34: =TRIM(Indice2026!$K$6) -> Porcentaje | F34: Elaborado por el IMCO con datos de los formatos 911 de la SEP, Conapo e IMSS 2025 (con datos 2024)
A35: Baja California | B35: =TRIM(Indice2026!$K$3) -> Cobertura de cuidados en la primera infancia | C35: =Indice2026!K14 -> 33.946358 | D35: =TRIM(Indice2026!$K$5) -> Porcentaje de infancias de 0 a 5 años inscritos en una guardería, centro de cuidados o preescolar | E35: =TRIM(Indice2026!$K$6) -> Porcentaje | F35: Elaborado por el IMCO con datos de los formatos 911 de la SEP, Conapo e IMSS 2025 (con datos 2024)
A36: Baja California Sur | B36: =TRIM(Indice2026!$K$3) -> Cobertura de cuidados en la primera infancia | C36: =Indice2026!K15 -> 37.128528 | D36: =TRIM(Indice2026!$K$5) -> Porcentaje de infancias de 0 a 5 años inscritos en una guardería, centro de cuidados o preescolar | E36: =TRIM(Indice2026!$K$6) -> Porcentaje | F36: Elaborado por el IMCO con datos de los formatos 911 de la SEP, Conapo e IMSS 2025 (con datos 2024)
A37: Campeche | B37: =TRIM(Indice2026!$K$3) -> Cobertura de cuidados en la primera infancia | C37: =Indice2026!K16 -> 42.467803 | D37: =TRIM(Indice2026!$K$5) -> Porcentaje de infancias de 0 a 5 años inscritos en una guardería, centro de cuidados o preescolar | E37: =TRIM(Indice2026!$K$6) -> Porcentaje | F37: Elaborado por el IMCO con datos de los formatos 911 de la SEP, Conapo e IMSS 2025 (con datos 2024)
A38: Chiapas | B38: =TRIM(Indice2026!$K$3) -> Cobertura de cuidados en la primera infancia | C38: =Indice2026!K19 -> 36.820917 | D38: =TRIM(Indice2026!$K$5) -> Porcentaje de infancias de 0 a 5 años inscritos en una guardería, centro de cuidados o preescolar | E38: =TRIM(Indice2026!$K$6) -> Porcentaje | F38: Elaborado por el IMCO con datos de los formatos 911 de la SEP, Conapo e IMSS 2025 (con datos 2024)
A39: Chihuahua | B39: =TRIM(Indice2026!$K$3) -> Cobertura de cuidados en la primera infancia | C39: =Indice2026!K20 -> 38.376758 | D39: =TRIM(Indice2026!$K$5) -> Porcentaje de infancias de 0 a 5 años inscritos en una guardería, centro de cuidados o preescolar | E39: =TRIM(Indice2026!$K$6) -> Porcentaje | F39: Elaborado por el IMCO con datos de los formatos 911 de la SEP, Conapo e IMSS 2025 (con datos 2024)
A40: Ciudad de México | B40: =TRIM(Indice2026!$K$3) -> Cobertura de cuidados en la primera infancia | C40: =Indice2026!K21 -> 43.79633 | D40: =TRIM(Indice2026!$K$5) -> Porcentaje de infancias de 0 a 5 años inscritos en una guardería, centro de cuidados o preescolar | E40: =TRIM(Indice2026!$K$6) -> Porcentaje | F40: Elaborado por el IMCO con datos de los formatos 911 de la SEP, Conapo e IMSS 2025 (con datos 2024)
A41: Coahuila | B41: =TRIM(Indice2026!$K$3) -> Cobertura de cuidados en la primera infancia | C41: =Indice2026!K17 -> 44.574509 | D41: =TRIM(Indice2026!$K$5) -> Porcentaje de infancias de 0 a 5 años inscritos en una guardería, centro de cuidados o preescolar | E41: =TRIM(Indice2026!$K$6) -> Porcentaje | F41: Elaborado por el IMCO con datos de los formatos 911 de la SEP, Conapo e IMSS 2025 (con datos 2024)
A42: Colima | B42: =TRIM(Indice2026!$K$3) -> Cobertura de cuidados en la primera infancia | C42: =Indice2026!K18 -> 47.907459 | D42: =TRIM(Indice2026!$K$5) -> Porcentaje de infancias de 0 a 5 años inscritos en una guardería, centro de cuidados o preescolar | E42: =TRIM(Indice2026!$K$6) -> Porcentaje | F42: Elaborado por el IMCO con datos de los formatos 911 de la SEP, Conapo e IMSS 2025 (con datos 2024)
...
